Workbook

Sheet CPX_Summary
A1: DataSet/Point | B1: Comment | C1: Phase | D1: Category | E1: Shape | F1: Grain_Name | G1: Profile_Number | H1: Paired_Grains | I1: Marked_bad | J1: Ignore | K1: Sample | L1: Collection Date | M1: Na2O | N1: MgO | O1: SiO2 | P1: CaO | Q1: Cr2O3 | R1: FeO | S1: K2O | T1: Al2O3 | U1: P2O5 | V1: TiO2 | W1: MnO | X1: NiO | Y1: Total | Z1: Mg# | AA1: Cr# | AB1: X | AC1: Y | AD1: Z | AE1: X-Distance from Edge | AF1: Image_X | AG1: Image_Y | AH1: X_mm | AI1: Y_mm | AJ1: Y_mm_offset | AK1: Edge distance x mm | AL1: Grain Profile Distance to Rim | AN1: Cr2O3 + Al2O3 | AO1: Na2O/Al2O3
B2: exterior summary | C2: cpx | D2: summary avg | J2: yes | K2: GCB1 | L2: 43282 | M2: 0.475615 | N2: 17.048971 | O2: 52.825532 | P2: 22.786213 | Q2: 0.53999813 | R2: 2.7434775 | T2: 3.9100169 | V2: 0.0994775 | W2: 0.1015675 | X2: 0.0458675 | Y2: 100.57672 | Z2: 91.719706 | AA2: =(Q2/151.99)/((Q2/151.99)+(T2/101.96))*100 -> 8.4790814 | AN2: =Q2+T2 -> 4.450015 | AO2: =M2/T2 -> 0.12164014
B3: Exterior core summary | C3: cpx | D3: summary avg | J3: yes | K3: GCB1 | L3: 43282 | M3: 0.472396 | N3: 17.035197 | O3: 52.839839 | P3: 22.782294 | Q3: 0.531355 | R3: 2.722291 | T3: 3.908686 | V3: 0.100054 | W3: 0.101827 | X3: 0.040391 | Y3: 100.53432 | Z3: 91.771805 | AA3: =(Q3/151.99)/((Q3/151.99)+(T3/101.96))*100 -> 8.3573121 | AN3: =Q3+T3 -> 4.440041 | AO3: =M3/T3 -> 0.12085801
B4: R-20_cpx-1_A | C4: cpx | D4: Primary | K4: GCB1 | L4: 43282 | M4: 0.4794875 | N4: 17.172005 | O4: 52.755327 | P4: 22.79006 | Q4: 0.55725 | R4: 2.705965 | T4: 3.92388 | V4: 0.09947 | W4: 0.1033375 | X4: 0.03901 | Y4: 100.62578 | Z4: 91.877177 | AA4: =(Q4/151.99)/((Q4/151.99)+(T4/101.96))*100 -> 8.6981839 | AN4: =Q4+T4 -> 4.48113 | AO4: =M4/T4 -> 0.12219729
B5: R-21_cpx-1_B | C5: cpx | D5: Primary | K5: GCB1 | L5: 43282 | M5: 0.47114333 | N5: 16.831303 | O5: 52.564087 | P5: 22.730527 | Q5: 0.57247 | R5: 2.7486267 | T5: 3.96884 | V5: 0.096473333 | W5: 0.10085667 | X5: 0.045616667 | Y5: 100.12994 | Z5: 91.608178 | AA5: =(Q5/151.99)/((Q5/151.99)+(T5/101.96))*100 -> 8.8224994 | AN5: =Q5+T5 -> 4.54131 | AO5: =M5/T5 -> 0.11871059
B6: R-22_cpx-1_C | C6: cpx | D6: Primary | K6: GCB1 | L6: 43282 | M6: 0.46419333 | N6: 17.05668 | O6: 53.228273 | P6: 22.823707 | Q6: 0.45571333 | R6: 2.7177233 | T6: 3.8282733 | V6: 0.10441333 | W6: 0.10078333 | X6: 0.037006667 | Y6: 100.81677 | Z6: 91.794937 | AA6: =(Q6/151.99)/((Q6/151.99)+(T6/101.96))*100 -> 7.3949979 | AN6: =Q6+T6 -> 4.2839867 | AO6: =M6/T6 -> 0.12125397
B7: exterior rim summary | C7: cpx | D7: summary avg | J7: yes | K7: GCB1 | L7: 43282 | M7: 0.48098 | N7: 17.071927 | O7: 52.801687 | P7: 22.792745 | Q7: 0.55440333 | R7: 2.7787883 | T7: 3.912235 | V7: 0.098516667 | W7: 0.101135 | X7: 0.054995 | Y7: 100.64738 | Z7: 91.632873 | AA7: =(Q7/151.99)/((Q7/151.99)+(T7/101.96))*100 -> 8.6811296 | AN7: =Q7+T7 -> 4.4666383 | AO7: =M7/T7 -> 0.12294251
B8: R-20_cpx-1_B | C8: cpx | D8: Primary | K8: GCB1 | L8: 43282 | M8: 0.48651667 | N8: 17.066947 | O8: 52.390387 | P8: 22.807563 | Q8: 0.58353 | R8: 2.7784467 | T8: 3.94813 | V8: 0.099026667 | W8: 0.09764 | X8: 0.052036667 | Y8: 100.3102 | Z8: 91.632109 | AA8: =(Q8/151.99)/((Q8/151.99)+(T8/101.96))*100 -> 9.0204904 | AN8: =Q8+T8 -> 4.53166 | AO8: =M8/T8 -> 0.12322711
B9: R-22_cpx-1_A | C9: cpx | D9: Primary | K9: GCB1 | L9: 43282 | M9: 0.47544333 | N9: 17.076907 | O9: 53.212987 | P9: 22.777927 | Q9: 0.52527667 | R9: 2.77913 | T9: 3.87634 | V9: 0.098006667 | W9: 0.10463 | X9: 0.057953333 | Y9: 100.98457 | Z9: 91.633638 | AA9: =(Q9/151.99)/((Q9/151.99)+(T9/101.96))*100 -> 8.3328715 | AN9: =Q9+T9 -> 4.4016167 | AO9: =M9/T9 -> 0.12265264
B10: interior summary | C10: cpx | D10: summary avg | J10: yes | K10: GCB1 | L10: 43282 | M10: 0.45209783 | N10: 17.038547 | O10: 52.138069 | P10: 22.724453 | Q10: 0.60003957 | R10: 2.7435409 | T10: 3.9786835 | V10: 0.1248113 | W10: 0.096353913 | X10: 0.04847913 | Y10: 99.945074 | Z10: 91.714995 | AA10: =(Q10/151.99)/((Q10/151.99)+(T10/101.96))*100 -> 9.1875689 | AN10: =Q10+T10 -> 4.578723 | AO10: =M10/T10 -> 0.11363001
B11: Interior core Summary | C11: cpx | D11: summary avg | J11: yes | K11: GCB1 | L11: 43282 | M11: 0.45672182 | N11: 17.040825 | O11: 52.02203 | P11: 22.77611 | Q11: 0.51027091 | R11: 2.7724173 | T11: 3.8504191 | V11: 0.10937727 | W11: 0.10377182 | X11: 0.047886364 | Y11: 99.689823 | Z11: 91.635398 | AA11: =(Q11/151.99)/((Q11/151.99)+(T11/101.96))*100 -> 8.1643035 | AN11: =Q11+T11 -> 4.36069 | AO11: =M11/T11 -> 0.11861613
B12: R-30_cpx-1_A | C12: cpx | D12: Primary | K12: GCB1 | L12: 43282 | M12: 0.4430325 | N12: 17.100848 | O12: 52.22581 | P12: 22.850268 | Q12: 0.36508 | R12: 2.738065 | T12: 3.69381 | V12: 0.10852 | W12: 0.1007425 | X12: 0.04077 | Y12: 99.666957 | Z12: 91.758307 | AA12: =(Q12/151.99)/((Q12/151.99)+(T12/101.96))*100 -> 6.2179607 | AN12: =Q12+T12 -> 4.05889 | AO12: =M12/T12 -> 0.11993917
B13: R-30_cpx-2_A | C13: cpx | D13: Primary | K13: GCB1 | L13: 43282 | M13: 0.45443 | N13: 16.84114 | O13: 51.251617 | P13: 22.637477 | Q13: 0.58720333 | R13: 2.8701233 | T13: 3.9718367 | V13: 0.10792667 | W13: 0.10573667 | X13: 0.055176667 | Y13: 98.882657 | Z13: 91.273686 | AA13: =(Q13/151.99)/((Q13/151.99)+(T13/101.96))*100 -> 9.0228601 | AN13: =Q13+T13 -> 4.55904 | AO13: =M13/T13 -> 0.11441306
B14: R-31_cpx-1_B | C14: cpx | D14: Primary | K14: GCB1 | L14: 43282 | M14: 0.47225333 | N14: 17.121513 | O14: 52.24239 | P14: 22.819367 | Q14: 0.59936667 | R14: 2.7448267 | T14: 3.9133367 | V14: 0.1111 | W14: 0.11193 | X14: 0.05376 | Y14: 100.18982 | Z14: 91.748451 | AA14: =(Q14/151.99)/((Q14/151.99)+(T14/101.96))*100 -> 9.317194 | AN14: =Q14+T14 -> 4.5127033 | AO14: =M14/T14 -> 0.12067792
B15: R-31_cpx-2_A | C15: cpx | D15: Primary | K15: GCB1 | L15: 43282 | M15: 0.47176 | N15: 17.15773 | O15: 52.85707 | P15: 22.76561 | Q15: 0.59295 | R15: 2.69948 | T15: 3.92385 | V15: 0.11199 | W15: 0.08552 | X15: 0.03686 | Y15: 100.7028 | Z15: 91.88974 | AA15: =(Q15/151.99)/((Q15/151.99)+(T15/101.96))*100 -> 9.2042039 | AN15: =Q15+T15 -> 4.5168 | AO15: =M15/T15 -> 0.12022886
B16: Interior rim Summary | C16: cpx | D16: summary avg | J16: yes | K16: GCB1 | L16: 43282 | M16: 0.45744571 | N16: 16.971414 | O16: 52.80189 | P16: 22.853267 | Q16: 0.54578714 | R16: 2.7401214 | T16: 3.9094814 | V16: 0.11012857 | W16: 0.089055714 | X16: 0.049614286 | Y16: 100.5282 | Z16: 91.693826 | AA16: =(Q16/151.99)/((Q16/151.99)+(T16/101.96))*100 -> 8.5632701 | AN16: =Q16+T16 -> 4.4552686 | AO16: =M16/T16 -> 0.11700931
B17: R-30_cpx-1_B | C17: cpx | D17: Primary | K17: GCB1 | L17: 43282 | M17: 0.44823333 | N17: 16.687283 | O17: 52.95176 | P17: 22.770447 | Q17: 0.56689667 | R17: 2.7147733 | T17: 3.9250033 | V17: 0.1065 | W17: 0.08146 | X17: 0.060373333 | Y17: 100.31274 | Z17: 91.636605 | AA17: =(Q17/151.99)/((Q17/151.99)+(T17/101.96))*100 -> 8.8331505 | AN17: =Q17+T17 -> 4.4919 | AO17: =M17/T17 -> 0.11419948
B18: R-31_cpx-1_A | C18: cpx | D18: Primary | K18: GCB1 | L18: 43282 | M18: 0.46082667 | N18: 17.234863 | O18: 52.789957 | P18: 22.94513 | Q18: 0.50548333 | R18: 2.7244667 | T18: 3.8829967 | V18: 0.10978667 | W18: 0.096693333 | X18: 0.03792 | Y18: 100.7881 | Z18: 91.854626 | AA18: =(Q18/151.99)/((Q18/151.99)+(T18/101.96))*100 -> 8.0314502 | AN18: =Q18+T18 -> 4.38848 | AO18: =M18/T18 -> 0.1186781
B19: R-31_cpx-2_B | C19: cpx | D19: Primary | K19: GCB1 | L19: 43282 | M19: 0.47494 | N19: 17.03346 | O19: 52.38808 | P19: 22.82614 | Q19: 0.60337 | R19: 2.86313 | T19: 3.94237 | V19: 0.12204 | W19: 0.08893 | X19: 0.05242 | Y19: 100.3949 | Z19: 91.383091 | AA19: =(Q19/151.99)/((Q19/151.99)+(T19/101.96))*100 -> 9.3109889 | AN19: =Q19+T19 -> 4.54574 | AO19: =M19/T19 -> 0.12047068
B20: Interior Melt Pocket | C20: cpx | D20: summary avg | J20: yes | K20: GCB1 | L20: 43282 | AA20: =(Q20/151.99)/((Q20/151.99)+(T20/101.96))*100 -> #DIV/0! | AN20: =Q20+T20 -> 0 | AO20: =M20/T20 -> #DIV/0!
B21: R-30_cpx-_melt pocket | C21: cpx | D21: MP | K21: GCB1 | L21: 43282 | M21: 0.51019 | N21: 17.203173 | O21: 51.504407 | P21: 22.55198 | Q21: 0.6242 | R21: 2.7860633 | T21: 3.9784233 | V21: 0.11279 | W21: 0.09233 | X21: 0.05398 | Y21: 99.41755 | Z21: 91.67136 | AA21: =(Q21/151.99)/((Q21/151.99)+(T21/101.96))*100 -> 9.5228411 | AN21: =Q21+T21 -> 4.6026233 | AO21: =M21/T21 -> 0.12823924
B22: R-30_cpx-3_melt pocket | C22: cpx | D22: MP | K22: GCB1 | L22: 43282 | M22: 0.32081 | N22: 17.014045 | O22: 51.403405 | P22: 22.2482 | Q22: 1.24741 | R22: 2.532905 | T22: 4.926735 | V22: 0.27912 | W22: 0.087135 | X22: 0.039515 | Y22: 100.09929 | Z22: 92.292319 | AA22: =(Q22/151.99)/((Q22/151.99)+(T22/101.96))*100 -> 14.518935 | AN22: =Q22+T22 -> 6.174145 | AO22: =M22/T22 -> 0.065116147
B23: Exterior Melt Pocket | C23: cpx | D23: summary avg | J23: yes | K23: GCB1 | L23: 43282 | AA23: =(Q23/151.99)/((Q23/151.99)+(T23/101.96))*100 -> #DIV/0! | AN23: =Q23+T23 -> 0 | AO23: =M23/T23 -> #DIV/0!
B24: core | C24: cpx | D24: summary avg | J24: yes | K24: GCB1 | L24: 43282 | M24: 0.48332333 | N24: 17.01371 | O24: 51.86764 | P24: 22.658477 | Q24: 0.51981667 | R24: 2.73363 | T24: 3.89564 | V24: 0.11156 | W24: 0.10721333 | X24: 0.055043333 | Y24: 99.446053 | Z24: 91.731978 | AA24: =(Q24/151.99)/((Q24/151.99)+(T24/101.96))*100 -> 8.215874 | AN24: =Q24+T24 -> 4.4154567 | AO24: =M24/T24 -> 0.12406776
B25: R-11_cpx-1_A | C25: cpx | D25: maybe primary | K25: GCB1 | L25: 43282 | M25: 0.48332333 | N25: 17.01371 | O25: 51.86764 | P25: 22.658477 | Q25: 0.51981667 | R25: 2.73363 | T25: 3.89564 | V25: 0.11156 | W25: 0.10721333 | X25: 0.055043333 | Y25: 99.446053 | Z25: 91.731978 | AA25: =(Q25/151.99)/((Q25/151.99)+(T25/101.96))*100 -> 8.215874 | AN25: =Q25+T25 -> 4.4154567 | AO25: =M25/T25 -> 0.12406776
B26: R-11_cpx-_Melt pocket | C26: cpx | D26: MP | K26: GCB1 | L26: 43282 | M26: 0.32538 | N26: 15.95351 | O26: 50.79133 | P26: 23.462555 | Q26: 1.1376 | R26: 2.34008 | T26: 6.13983 | V26: 0.382635 | W26: 0.05989 | X26: 0.05584 | Y26: 100.64865 | Z26: 92.394327 | AA26: =(Q26/151.99)/((Q26/151.99)+(T26/101.96))*100 -> 11.055245 | AN26: =Q26+T26 -> 7.27743 | AO26: =M26/T26 -> 0.052994953
A27: 1 / 1 . | B27: PMR53_CPX_STD_1 | D27: standard | J27: yes | K27: PMR53 | L27: 44013 | M27: 2.111062 | N27: 18.19391 | O27: 54.19711 | P27: 13.7895 | Q27: 0.153725 | R27: 6.95713 | T27: 2.924824 | U27: 0.134615 | V27: 0.367157 | W27: 0.155738 | Y27: 98.98478 | Z27: 82.33751 | AA27: =(Q27/151.99)/((Q27/151.99)+(T27/101.96))*100 -> 3.4057355 | AN27: =Q27+T27 -> 3.078549 | AO27: =M27/T27 -> 0.72177403
A28: 2 / 1 . | B28: AZ18_WHT06_CPX4_phenocryst_core | D28: phenocryst | J28: yes | K28: AZ18WHT06 Scoria | L28: 44013 | M28: 0.337847 | N28: 14.34405 | O28: 48.41978 | P28: 22.82644 | Q28: 0.314473 | R28: 6.27402 | T28: 5.669125 | U28: 0.22238 | V28: 1.466736 | W28: 0.134057 | Y28: 100.0089 | Z28: 80.297321 | AA28: =(Q28/151.99)/((Q28/151.99)+(T28/101.96))*100 -> 3.5876878 | AN28: =Q28+T28 -> 5.983598 | AO28: =M28/T28 -> 0.059594205
A29: 3 / 1 . | B29: AZ18_WHT06_CPX4_phenocryst_Long_rim | D29: phenocryst | K29: AZ18WHT06 Scoria | L29: 44013 | M29: 0.241652 | N29: 16.0621 | O29: 51.09752 | P29: 22.30197 | Q29: 0.080693 | R29: 6.132524 | T29: 3.187994 | U29: 0.238201 | V29: 0.880195 | W29: 0.132114 | Y29: 100.355 | Z29: 82.359847 | AA29: =(Q29/151.99)/((Q29/151.99)+(T29/101.96))*100 -> 1.6696323 | AN29: =Q29+T29 -> 3.268687 | AO29: =M29/T29 -> 0.075800645
A30: 4 / 1 . | B30: AZ18_WHT06_CPX4_phenocryst_narrow_rim | D30: phenocryst | K30: AZ18WHT06 Scoria | L30: 44013 | M30: 0.320943 | N30: 13.81878 | O30: 48.26093 | P30: 22.83122 | Q30: 0.1659 | R30: 6.597981 | T30: 6.027592 | U30: 0.238976 | V30: 1.645312 | W30: 0.112514 | Y30: 100.0201 | Z30: 78.87369 | AA30: =(Q30/151.99)/((Q30/151.99)+(T30/101.96))*100 -> 1.8128915 | AN30: =Q30+T30 -> 6.193492 | AO30: =M30/T30 -> 0.053245641
A31: 5 / 1 . | B31: AZ18_WHT06_CPX_Xenocryst_prof1_rim | D31: xenocryst | K31: AZ18WHT06 Xenocrysts_rim | L31: 44013 | M31: 0.355506 | N31: 13.06295 | O31: 47.68927 | P31: 22.53806 | Q31: 0.172154 | R31: 7.049124 | T31: 5.547668 | U31: 0.264166 | V31: 2.382529 | W31: 0.123298 | Y31: 99.18474 | Z31: 76.762359 | AA31: =(Q31/151.99)/((Q31/151.99)+(T31/101.96))*100 -> 2.0392642 | AL31: 0 | AN31: =Q31+T31 -> 5.719822 | AO31: =M31/T31 -> 0.064082061
A32: 5 / 2 . | B32: AZ18_WHT06_CPX_Xenocryst_prof1_rim | D32: xenocryst | K32: AZ18WHT06 Xenocrysts_rim | L32: 44013 | M32: 0.3808 | N32: 13.20668 | O32: 47.68296 | P32: 22.86014 | Q32: 0.146132 | R32: 6.876187 | T32: 5.384778 | U32: 0.24787 | V32: 2.273811 | W32: 0.115374 | Y32: 99.17473 | Z32: 77.394507 | AA32: =(Q32/151.99)/((Q32/151.99)+(T32/101.96))*100 -> 1.787957 | AL32: 2.5 | AN32: =Q32+T32 -> 5.53091 | AO32: =M32/T32 -> 0.070717864
A33: 5 / 3 . | B33: AZ18_WHT06_CPX_Xenocryst_prof1_rim | D33: xenocryst | K33: AZ18WHT06 Xenocrysts_rim | L33: 44013 | M33: 0.358696 | N33: 13.14649 | O33: 48.20082 | P33: 23.13826 | Q33: 0.163253 | R33: 6.842701 | T33: 5.282504 | U33: 0.257604 | V33: 2.206128 | W33: 0.102946 | Y33: 99.69941 | Z33: 77.399987 | AA33: =(Q33/151.99)/((Q33/151.99)+(T33/101.96))*100 -> 2.0310683 | AL33: 5 | AN33: =Q33+T33 -> 5.445757 | AO33: =M33/T33 -> 0.067902646
A34: 5 / 4 . | B34: AZ18_WHT06_CPX_Xenocryst_prof1_rim | D34: xenocryst | K34: AZ18WHT06 Xenocrysts_rim | L34: 44013 | M34: 0.352207 | N34: 13.40935 | O34: 48.2681 | P34: 23.37511 | Q34: 0.193059 | R34: 6.78707 | T34: 5.258124 | U34: 0.254132 | V34: 2.19282 | W34: 0.109625 | Y34: 100.1996 | Z34: 77.885338 | AA34: =(Q34/151.99)/((Q34/151.99)+(T34/101.96))*100 -> 2.4038466 | AL34: 7.5 | AN34: =Q34+T34 -> 5.451183 | AO34: =M34/T34 -> 0.066983396
A35: 5 / 5 . | B35: AZ18_WHT06_CPX_Xenocryst_prof1_rim | D35: xenocryst | K35: AZ18WHT06 Xenocrysts_rim | L35: 44013 | M35: 0.358777 | N35: 13.5943 | O35: 48.51057 | P35: 23.01702 | Q35: 0.201612 | R35: 6.455187 | T35: 5.151327 | U35: 0.242253 | V35: 2.122547 | W35: 0.097491 | Y35: 99.75108 | Z35: 78.96522 | AA35: =(Q35/151.99)/((Q35/151.99)+(T35/101.96))*100 -> 2.5583313 | AL35: 10.001999 | AN35: =Q35+T35 -> 5.352939 | AO35: =M35/T35 -> 0.069647491
A36: 5 / 6 . | B36: AZ18_WHT06_CPX_Xenocryst_prof1_rim | D36: xenocryst | K36: AZ18WHT06 Xenocrysts_rim | L36: 44013 | M36: 0.354419 | N36: 13.39523 | O36: 48.46143 | P36: 23.09287 | Q36: 0.206517 | R36: 6.314919 | T36: 5.155789 | U36: 0.242283 | V36: 2.135337 | W36: 0.104836 | Y36: 99.46364 | Z36: 79.08486 | AA36: =(Q36/151.99)/((Q36/151.99)+(T36/101.96))*100 -> 2.6167354 | AL36: 12.501999 | AN36: =Q36+T36 -> 5.362306 | AO36: =M36/T36 -> 0.068741952
A37: 5 / 7 . | B37: AZ18_WHT06_CPX_Xenocryst_prof1_rim | D37: xenocryst | K37: AZ18WHT06 Xenocrysts_rim | L37: 44013 | M37: 0.381869 | N37: 13.41788 | O37: 48.00957 | P37: 23.33621 | Q37: 0.201938 | R37: 6.591768 | T37: 5.409098 | U37: 0.240502 | V37: 2.157881 | W37: 0.094979 | Y37: 99.84171 | Z37: 78.394915 | AA37: =(Q37/151.99)/((Q37/151.99)+(T37/101.96))*100 -> 2.4432359 | AL37: 15.001999 | AN37: =Q37+T37 -> 5.611036 | AO37: =M37/T37 -> 0.070597538
A38: 5 / 8 . | B38: AZ18_WHT06_CPX_Xenocryst_prof1_rim | D38: xenocryst | K38: AZ18WHT06 Xenocrysts_rim | L38: 44013 | M38: 0.41265 | N38: 13.30764 | O38: 47.75115 | P38: 23.11993 | Q38: 0.249156 | R38: 6.227009 | T38: 5.706132 | U38: 0.240637 | V38: 2.218648 | W38: 0.103811 | Y38: 99.33676 | Z38: 79.207951 | AA38: =(Q38/151.99)/((Q38/151.99)+(T38/101.96))*100 -> 2.8458099 | AL38: 17.501999 | AN38: =Q38+T38 -> 5.955288 | AO38: =M38/T38 -> 0.072316939
A39: 5 / 9 . | B39: AZ18_WHT06_CPX_Xenocryst_prof1_rim | D39: xenocryst | K39: AZ18WHT06 Xenocrysts_rim | L39: 44013 | M39: 0.407868 | N39: 13.36325 | O39: 47.8021 | P39: 23.20823 | Q39: 0.313748 | R39: 6.045313 | T39: 5.637379 | U39: 0.259502 | V39: 2.131324 | W39: 0.094109 | Y39: 99.26283 | Z39: 79.758836 | AA39: =(Q39/151.99)/((Q39/151.99)+(T39/101.96))*100 -> 3.5991457 | AL39: 20.001999 | AN39: =Q39+T39 -> 5.951127 | AO39: =M39/T39 -> 0.072350644
A40: 5 / 10 . | B40: AZ18_WHT06_CPX_Xenocryst_prof1_rim | D40: xenocryst | K40: AZ18WHT06 Xenocrysts_rim | L40: 44013 | M40: 0.37586 | N40: 13.64319 | O40: 48.42814 | P40: 23.14179 | Q40: 0.330834 | R40: 6.017361 | T40: 5.244934 | U40: 0.232737 | V40: 1.999372 | W40: 0.104403 | Y40: 99.51862 | Z40: 80.16526 | AA40: =(Q40/151.99)/((Q40/151.99)+(T40/101.96))*100 -> 4.0596287 | AL40: 22.501999 | AN40: =Q40+T40 -> 5.575768 | AO40: =M40/T40 -> 0.071661531
...

Sheet CPX_Published
A1: Source | B1: Grain_Name | C1: Category | D1: Marked_bad | E1: Ignore | F1: SiO2 | G1: TiO2 | H1: Al2O3 | I1: Cr2O3 | J1: FeO | K1: MnO | L1: NiO | M1: MgO | N1: CaO | O1: Na2O | P1: Total | Q1: Mg# | R1: Cr# | T1: Ce
A2: Alibert 1994 | B2: TRU 1 | C2: Alibert 1994 | F2: 51.69 | G2: 0.18 | H2: 4.6 | I2: 0.58 | J2: 2.9 | K2: 0.06 | L2: 0.06 | M2: 16.48 | N2: 21.81 | O2: 0.73 | P2: 99.1 | Q2: 91 | R2: 7.83859 | T2: 14.2
A3: Alibert 1994 | B3: TRU 1 | C3: Alibert 1994 | F3: 51.83 | G3: 0.13 | H3: 4.05 | I3: 0.4 | J3: 2.88 | K3: 0.08 | L3: 0.03 | M3: 16.37 | N3: 22.21 | O3: 0.62 | P3: 98.59 | Q3: 91.03 | R3: 6.1431624 | T3: 14.2
A4: Alibert 1994 | B4: TRU 2 | C4: Alibert 1994 | F4: 51.75 | G4: 0.13 | H4: 5.08 | I4: 0.7 | J4: 3.13 | K4: 0.1 | L4: 0.06 | M4: 16.35 | N4: 21.21 | O4: 0.93 | P4: 99.45 | Q4: 90.3 | R4: 8.4937238 | T4: 0.483
A5: Alibert 1994 | B5: TRU 2 | C5: Alibert 1994 | F5: 51.8 | G5: 0.15 | H5: 5.14 | I5: 0.62 | J5: 2.99 | K5: 0.12 | L5: 0.03 | M5: 15.94 | N5: 21.28 | O5: 0.92 | P5: 98.97 | Q5: 90.5 | R5: 7.5416667 | T5: 0.483
A6: Alibert 1994 | B6: TRU 3 | C6: Alibert 1994 | F6: 53.16 | G6: 0.03 | H6: 3.72 | I6: 0.44 | J6: 2.85 | K6: 0.1 | L6: 0.03 | M6: 16.85 | N6: 22.34 | O6: 0.8 | P6: 100.34 | Q6: 91.33 | R6: 7.3099415 | T6: 5.78
A7: Alibert 1994 | B7: TRU 3 | C7: Alibert 1994 | F7: 52.22 | G7: 0.07 | H7: 4.44 | I7: 0.64 | J7: 2.96 | K7: 0.1 | L7: 0.05 | M7: 16.67 | N7: 21.75 | O7: 0.81 | P7: 99.72 | Q7: 90.93 | R7: 8.7954111 | T7: 5.78
A8: Alibert 1994 | B8: TRU 4 | C8: Alibert 1994 | F8: 54.45 | G8: 0 | H8: 2.47 | I8: 0.09 | J8: 2.36 | K8: 0.13 | L8: 0 | M8: 17.29 | N8: 23.95 | O8: 0.36 | P8: 101.13 | Q8: 92.9 | R8: 2.3364486 | T8: 2.57
A9: Alibert 1994 | B9: TRU 4 | C9: Alibert 1994 | F9: 54.36 | G9: 0.01 | H9: 2.94 | I9: 0.12 | J9: 2.41 | K9: 0.12 | L9: 0.03 | M9: 17.15 | N9: 23.36 | O9: 0.42 | P9: 100.94 | Q9: 92.68 | R9: 2.7365129 | T9: 2.57
A10: Alibert 1994 | B10: TRU 5 | C10: Alibert 1994 | F10: 52.38 | G10: 0.05 | H10: 3.74 | I10: 0.54 | J10: 2.86 | K10: 0.07 | L10: 0.02 | M10: 16.83 | N10: 23.28 | O10: 0.38 | P10: 100.16 | Q10: 91.29 | R10: 8.8737201 | T10: 96
A11: Alibert 1994 | B11: TRU 5 | C11: Alibert 1994 | F11: 52.42 | G11: 0.09 | H11: 3.62 | I11: 0.46 | J11: 2.8 | K11: 0.07 | L11: 0.08 | M11: 16.96 | N11: 22.96 | O11: 0.36 | P11: 99.84 | Q11: 91.54 | R11: 7.8744819 | T11: 96
A12: Alibert 1994 | B12: TRU 6 | C12: Alibert 1994 | F12: 52.96 | G12: 0.09 | H12: 3.91 | I12: 0.61 | J12: 2.83 | K12: 0.06 | L12: 0.02 | M12: 16.9 | N12: 23.3 | O12: 0.33 | P12: 101.02 | Q12: 91.42 | R12: 9.4535519 | T12: 17.9
A13: Alibert 1994 | B13: TRU 6 | C13: Alibert 1994 | F13: 52.98 | G13: 0.11 | H13: 3.83 | I13: 0.47 | J13: 2.59 | K13: 0 | L13: 0 | M13: 16.76 | N13: 23.05 | O13: 0.33 | P13: 100.14 | Q13: 92.02 | R13: 7.5268817 | T13: 17.9
... A21: Alibert 1994 | B21: TRU 31 | C21: Alibert 1994 | F21: 52.05 | G21: 0.29 | H21: 4.76 | I21: 1 | J21: 3.03 | K21: 0.07 | L21: 0.03 | M21: 16.35 | N21: 21.21 | O21: 0.84 | P21: 99.63 | Q21: 90.57 | R21: 12.360515 | T21: 18.7
A22: Li et al. 2008 | B22: GC2a | C22: Li et al. 2008 | F22: 53.3 | H22: 1.71 | I22: 0.32 | J22: 2.04 | K22: 0.08 | L22: 0.05 | M22: 17.87 | N22: 24.54 | O22: 0.29 | P22: 100.19 | Q22: 93.981407 | R22: 11.153562
A23: Li et al. 2008 | B23: GC2b | C23: Li et al. 2008 | F23: 52.15 | G23: 0.11 | H23: 3.98 | I23: 0.44 | J23: 2.46 | K23: 0.09 | L23: 0.06 | M23: 16.75 | N23: 23.59 | O23: 0.59 | P23: 100.22 | Q23: 92.38825 | R23: 6.9042891
A24: Li et al. 2008 | B24: GC2c | C24: Li et al. 2008 | F24: 53.44 | G24: 0.04 | H24: 3.33 | I24: 0.41 | J24: 2.51 | K24: 0.09 | L24: 0.05 | M24: 16.99 | N24: 23.39 | O24: 0.56 | P24: 100.8 | Q24: 92.346693 | R24: 7.6294437
A25: Li et al. 2008 | B25: GC2e | C25: Li et al. 2008 | F25: 52.25 | G25: 0.12 | H25: 4.39 | I25: 0.43 | J25: 2.7 | K25: 0.1 | L25: 0.05 | M25: 16.62 | N25: 23.04 | O25: 0.74 | P25: 100.44 | Q25: 91.647776 | R25: 6.1657381
A26: Li et al. 2008 | B26: GC2x | C26: Li et al. 2008 | F26: 52.14 | G26: 0.08 | H26: 4.43 | I26: 0.43 | J26: 2.55 | K26: 0.08 | L26: 0.04 | M26: 16.36 | N26: 22.5 | O26: 0.45 | P26: 99.06 | Q26: 91.959196 | R26: 6.113469

Sheet Olivine Core Pivot Table
A3: Row Labels | B3: Average of CaO | C3: StdDev of CaO | D3: Count of CaO | E3: Average of Cr2O3 | F3: StdDev of Cr2O3 | G3: Average of Al2O3 | H3: StdDev of Al2O3 | I3: Count of Al2O3 | J3: Average of P2O5 | K3: StdDev of P2O5 | L3: Count of P2O5 | M3: Average of TiO2 | N3: StdDev of TiO2 | O3: Average of Fo# | P3: StdDev of Fo# | Q3: Count of Fo# | R3: Average of MnO | S3: StdDev of MnO
A4: yes | B4: 0.40163985 | C4: 1.5027749 | D4: 194 | E4: 0.066070944 | F4: 0.34673301 | G4: 0.53984525 | H4: 2.817824 | I4: 193 | J4: 0.017514534 | K4: 0.042718985 | L4: 167 | M4: 0.046325126 | N4: 0.25377501 | O4: 83.515517 | P4: 19.955259 | Q4: 193 | R4: 0.14750947 | S4: 0.049151458
A5: (blank) | B5: 0.11849237 | C5: 0.055286792 | D5: 1025 | E5: 0.0283592 | F5: 0.023151766 | G5: 0.022778581 | H5: 0.012748316 | I5: 993 | J5: 0.016186227 | K5: 0.0098958935 | L5: 846 | M5: 0.014524973 | N5: 0.0069079605 | O5: 86.510586 | P5: 8.7851064 | Q5: 1034 | R5: 0.16715258 | S5: 0.032053421
A6: core | B6: 0.050205254 | C6: 0.011513875 | D6: 261 | E6: 0.013209198 | F6: 0.0079598183 | G6: 0.0094071589 | H6: 0.0051283789 | I6: 235 | J6: 0.013414857 | K6: 0.0082913526 | L6: 175 | M6: 0.0088461149 | N6: 0.0042199664 | O6: 89.889057 | P6: 0.59652661 | Q6: 261 | R6: 0.1451253 | S6: 0.0090385268
A7: AZ18 WHT01 | B7: 0.056161645 | C7: 0.0087169533 | D7: 155 | E7: 0.015806462 | F7: 0.0082112014 | G7: 0.010827079 | H7: 0.0036766862 | I7: 151 | J7: 0.017452614 | K7: 0.0058201355 | L7: 101 | M7: 0.011175716 | N7: 0.0033382277 | O7: 89.726286 | P7: 0.18772353 | Q7: 155 | R7: 0.14582816 | S7: 0.0079620709
A8: AZ18 WHT06 | B8: 0.036855612 | C8: 0.0078540858 | D8: 49 | E8: 0.012200467 | F8: 0.0035317806 | G8: 0.00295675 | H8: 0.0027457834 | I8: 28 | J8: 0.0031193571 | K8: 0.0023104878 | L8: 28 | M8: 0.0056055306 | N8: 0.0034246151 | O8: 89.705827 | P8: 1.0730391 | Q8: 49 | R8: 0.14625408 | S8: 0.012202958
A9: GCB1 | B9: 0.043914167 | C9: 0.0032796961 | D9: 8 | E9: 0.008001875 | F9: 0.0032300607 | G9: 0.0056940476 | H9: 0.0017120993 | I9: 7 | M9: 0.003794375 | N9: 0.0028562785 | O9: 89.926819 | P9: 0.090526006 | Q9: 8 | R9: 0.15927333 | S9: 0.0058655542
A10: GCB1A R31 | B10: 0.055111632 | C10: 0.0051722644 | D10: 19 | E10: 0.020155526 | F10: 0.0058617009 | G10: 0.011458842 | H10: 0.0013301739 | I10: 19 | J10: 0.020675579 | K10: 0.0034980047 | L10: 19 | M10: 0.005238 | N10: 0.0024172671 | O10: 90.68362 | P10: 0.32865885 | Q10: 19 | R10: 0.14100874 | S10: 0.0049299932
A11: Xenocryst | B11: 0.039805233 | C11: 0.0058665192 | D11: 30 | E11: 0.0073264 | F11: 0.0061334115 | G11: 0.0078476 | H11: 0.0086196372 | I11: 30 | J11: 0.0038780741 | K11: 0.0023058257 | L11: 27 | M11: 0.0057350667 | N11: 0.0017725056 | O11: 90.516022 | P11: 0.096849131 | Q11: 30 | R11: 0.1384845 | S11: 0.0030314402
A12: rim | B12: 0.067840556 | C12: 0.019701809 | D12: 6 | E12: 0.0170125 | F12: 0.0080437169 | G12: 0.0081111111 | H12: 0.0042647683 | I12: 6 | M12: 0.0061105556 | N12: 0.0027488722 | O12: 90.313083 | P12: 0.46694524 | Q12: 6 | R12: 0.15672722 | S12: 0.0091175241
A13: (blank) | B13: 0.13776859 | C13: 0.041293465 | D13: 669 | E13: 0.035424864 | F13: 0.0225637 | G13: 0.026894155 | H13: 0.010274511 | I13: 663 | J13: 0.017405338 | K13: 0.010155301 | L13: 586 | M13: 0.016165917 | N13: 0.0061336378 | O13: 84.983345 | P13: 10.409887 | Q13: 678 | R13: 0.17578245 | S13: 0.030740922
A14: AZ18 WHT01 | B14: 0.10946954 | C14: 0.057105616 | D14: 92 | E14: 0.041011143 | F14: 0.023200155 | G14: 0.016663484 | H14: 0.010903723 | I14: 91 | J14: 0.015961824 | K14: 0.0088468225 | L14: 68 | M14: 0.016473424 | N14: 0.0075532678 | O14: 89.562777 | P14: 2.3750895 | Q14: 92 | R14: 0.14859255 | S14: 0.034189137
A15: AZ18 WHT06 | B15: 0.14430359 | C15: 0.032977189 | D15: 515 | E15: 0.021771556 | F15: 0.010791265 | G15: 0.028456502 | H15: 0.0076519808 | I15: 510 | J15: 0.016527581 | K15: 0.00870716 | L15: 470 | M15: 0.016481621 | N15: 0.0055536424 | O15: 85.251485 | P15: 3.0236986 | Q15: 515 | R15: 0.18213655 | S15: 0.026218146
A16: GCB1 | B16: 0.14595083 | C16: 0.0065702005 | D16: 2 | E16: 0.10557167 | F16: 0.047816918 | G16: 0.030263333 | H16: 0.0037382378 | I16: 2 | M16: 0.0062358333 | N16: 0.0020635733 | O16: 92.478 | P16: 0.1399077 | Q16: 2 | R16: 0.11407417 | S16: 0.00046786899
A17: GCB1A R31 | B17: 0.092379222 | C17: 0.021316586 | D17: 9 | E17: 0.038083556 | F17: 0.010031853 | G17: 0.016027111 | H17: 0.0074602841 | I17: 9 | J17: 0.017571556 | K17: 0.0096872407 | L17: 9 | M17: 0.0066393333 | N17: 0.0021073914 | O17: 91.691305 | P17: 0.28980088 | Q17: 9 | R17: 0.13299422 | S17: 0.004269293
A18: MP | B18: 0.20958 | C18: #DIV/0! | D18: 1 | E18: 0.10846 | F18: #DIV/0! | G18: 0.03265 | H18: #DIV/0! | I18: 1 | M18: 0.00934 | N18: #DIV/0! | O18: 93.104722 | P18: #DIV/0! | Q18: 1 | R18: 0.12209 | S18: #DIV/0!
A19: Phenocryst | B19: 0.158789 | C19: 0.036616448 | D19: 24 | E19: 0.039231708 | F19: 0.0072750247 | G19: 0.043692708 | H19: 0.0095706325 | I19: 24 | J19: 0.041060958 | K19: 0.0086374085 | L19: 24 | M19: 0.018311917 | N19: 0.0060904455 | O19: 86.523928 | P19: 2.219154 | Q19: 24 | R19: 0.18005383 | S19: 0.031537029
A20: San Carlos | B20: 0.10843875 | C20: 0.0058727118 | D20: 4 | E20: 0.021435 | F20: 0.0053645688 | G20: 0.040094 | H20: 0.00098752451 | I20: 4 | J20: 0.02405525 | K20: 0.001327223 | L20: 4 | M20: 0.00708425 | N20: 0.001367733 | O20: 90.211456 | P20: 0.054609161 | Q20: 4 | R20: 0.14526675 | S20: 0.0031263602
A21: Scoria | B21: 0.12762667 | C21: 0.087391079 | D21: 8 | E21: 0.026247917 | F21: 0.016426437 | G21: 0.026999167 | H21: 0.020013202 | I21: 8 | M21: 0.014089583 | N21: 0.010549368 | O21: 86.97516 | P21: 3.2796314 | Q21: 8 | R21: 0.18577292 | S21: 0.050569778
A22: Xenocryst | B22: 0.084359929 | C22: 0.040121062 | D22: 14 | E22: 0.013211286 | F22: 0.0078342183 | G22: 0.0099440714 | H22: 0.0069511944 | I22: 14 | J22: 0.0096666364 | K22: 0.015127672 | L22: 11 | M22: 0.0106645 | N22: 0.0054724791 | O22: 88.422389 | P22: 1.9386535 | Q22: 14 | R22: 0.15656371 | S22: 0.01902668
A23: (blank) | O23: 0 | P23: 0 | Q23: 9
A24: overgrowth | B24: 0.17726828 | C24: 0.04343575 | D24: 89 | E24: 0.044761103 | F24: 0.027152784 | G24: 0.028415247 | H24: 0.01774971 | I24: 89 | J24: 0.013487294 | K24: 0.009526 | L24: 85 | M24: 0.019411236 | N24: 0.0084597171 | O24: 87.981078 | P24: 4.0284095 | Q24: 89 | R24: 0.16758276 | S24: 0.050230274
A25: AZ18 WHT01 | B25: 0.1509839 | C25: 0.026385242 | D25: 30 | E25: 0.065452526 | F25: 0.035198334 | G25: 0.033873433 | H25: 0.025734292 | I25: 30 | J25: 0.0078287586 | K25: 0.0040325524 | L25: 29 | M25: 0.018657267 | N25: 0.0037719138 | O25: 91.392729 | P25: 0.4277291 | Q25: 30 | R25: 0.12382267 | S25: 0.010123802
A26: AZ18 WHT06 | B26: 0.19864188 | C26: 0.033263736 | D26: 25 | E26: 0.0530398 | F26: 0.0060971678 | G26: 0.02392556 | H26: 0.016670338 | I26: 25 | J26: 0.011592136 | K26: 0.0067781543 | L26: 22 | M26: 0.0154722 | N26: 0.0084413836 | O26: 87.544552 | P26: 3.7333354 | Q26: 25 | R26: 0.1713316 | S26: 0.050725243
A27: GCB1A R31 | B27: 0.14414863 | C27: 0.016723343 | D27: 8 | E27: 0.050801125 | F27: 0.0089316764 | G27: 0.027119375 | H27: 0.0040536107 | I27: 8 | J27: 0.00417575 | K27: 0.002254256 | L27: 8 | M27: 0.008286375 | N27: 0.0013123674 | O27: 92.004844 | P27: 0.24437351 | Q27: 8 | R27: 0.13578425 | S27: 0.0083973938
A28: Xenocryst | B28: 0.19723554 | C28: 0.051394941 | D28: 26 | E28: 0.026189923 | F28: 0.0071572459 | G28: 0.026833077 | H28: 0.0032149838 | I28: 26 | J28: 0.024267423 | K28: 0.0076003996 | L28: 26 | M28: 0.027491769 | N28: 0.0065432066 | O28: 83.226211 | P28: 0.81344841 | Q28: 26 | R28: 0.22425469 | S28: 0.017226396
A29: Grand Total | B29: 0.1635544 | C29: 0.6092246 | D29: 1219 | E29: 0.038644221 | F29: 0.1823162 | G29: 0.10692181 | H29: 1.1502594 | I29: 1186 | J29: 0.016405207 | K29: 0.019528311 | L29: 1013 | M29: 0.019585867 | N29: 0.1018844 | O29: 86.039479 | P29: 11.339371 | Q29: 1227 | R29: 0.16402644 | S29: 0.036031416
A30: Plots Below !!!
A34: Row Labels | B34: Average of CaO | C34: StdDev of CaO | D34: Count of CaO | E34: Average of Cr2O3 | F34: StdDev of Cr2O3 | G34: Average of Al2O3 | H34: StdDev of Al2O3 | I34: Count of Al2O3 | J34: Average of P2O5 | K34: StdDev of P2O5 | L34: Count of P2O5 | M34: Average of TiO2 | N34: StdDev of TiO2 | O34: Average of Fo# | P34: StdDev of Fo# | Q34: Count of Fo# | R34: Average of MnO | S34: StdDev of MnO
A35: Cores
A36: AZ18 WHT01 | B36: 0.056161645 | C36: 0.0087169533 | D36: 155 | E36: 0.015806462 | F36: 0.0082112014 | G36: 0.010827079 | H36: 0.0036766862 | I36: 151 | J36: 0.017452614 | K36: 0.0058201355 | L36: 101 | M36: 0.011175716 | N36: 0.0033382277 | O36: 89.726286 | P36: 0.18772353 | Q36: 155 | R36: 0.14582816 | S36: 0.0079620709
A37: AZ18 WHT06 | B37: 0.036855612 | C37: 0.0078540858 | D37: 49 | E37: 0.012200467 | F37: 0.0035317806 | G37: 0.00295675 | H37: 0.0027457834 | I37: 28 | J37: 0.0031193571 | K37: 0.0023104878 | L37: 28 | M37: 0.0056055306 | N37: 0.0034246151 | O37: 89.705827 | P37: 1.0730391 | Q37: 49 | R37: 0.14625408 | S37: 0.012202958
A39: GCB1A R31 | B39: 0.055111632 | C39: 0.0051722644 | D39: 19 | E39: 0.020155526 | F39: 0.0058617009 | G39: 0.011458842 | H39: 0.0013301739 | I39: 19 | J39: 0.020675579 | K39: 0.0034980047 | L39: 19 | M39: 0.005238 | N39: 0.0024172671 | O39: 90.68362 | P39: 0.32865885 | Q39: 19 | R39: 0.14100874 | S39: 0.0049299932
A40: Xenocrysts | B40: 0.039805233 | C40: 0.0058665192 | D40: 30 | E40: 0.0073264 | F40: 0.0061334115 | G40: 0.0078476 | H40: 0.0086196372 | I40: 30 | J40: 0.0038780741 | K40: 0.0023058257 | L40: 27 | M40: 0.0057350667 | N40: 0.0017725056 | O40: 90.516022 | P40: 0.096849131 | Q40: 30 | R40: 0.1384845 | S40: 0.0030314402
A42: overgrowth | Q42: 46
A43: AZ18 WHT01 | B43: 0.1509839 | C43: 0.026385242 | D43: 30 | E43: 0.065452526 | F43: 0.035198334 | G43: 0.033873433 | H43: 0.025734292 | I43: 30 | J43: 0.0078287586 | K43: 0.0040325524 | L43: 29 | M43: 0.018657267 | N43: 0.0037719138 | O43: 91.392729 | P43: 0.4277291 | Q43: 30 | R43: 0.12382267 | S43: 0.010123802
A44: AZ18 WHT06 | B44: 0.18170838 | C44: 0.024513463 | D44: 8 | E44: 0.0530398 | F44: 0.0060971678 | G44: 0.041164625 | H44: 0.020544039 | I44: 8 | J44: 0.002851 | K44: 0.0022807126 | L44: 5 | M44: 0.004968125 | N44: 0.0047114879 | O44: 92.846627 | P44: 0.39747729 | Q44: 8 | R44: 0.1713316 | S44: 0.050725243
A45: GCB1A R31 | B45: 0.14414863 | C45: 0.016723343 | D45: 8 | E45: 0.050801125 | F45: 0.0089316764 | G45: 0.027119375 | H45: 0.0040536107 | I45: 8 | J45: 0.00417575 | K45: 0.002254256 | L45: 8 | M45: 0.008286375 | N45: 0.0013123674 | O45: 92.004844 | P45: 0.24437351 | Q45: 8 | R45: 0.13578425 | S45: 0.0083973938
A46: Xenocryst | B46: 0.19723554 | C46: 0.051394941 | D46: 26 | E46: 0.026189923 | F46: 0.0071572459 | G46: 0.026833077 | H46: 0.0032149838 | I46: 26 | J46: 0.024267423 | K46: 0.0076003996 | L46: 26 | M46: 0.027491769 | N46: 0.0065432066 | O46: 83.226211 | P46: 0.81344841 | Q46: 26 | R46: 0.22425469 | S46: 0.017226396
A47: Phenocrysts | B47: 0.158789 | C47: 0.036616448 | D47: 24 | E47: 0.039231708 | F47: 0.0072750247 | G47: 0.043692708 | H47: 0.0095706325 | I47: 24 | J47: 0.041060958 | K47: 0.0086374085 | L47: 24 | M47: 0.018311917 | N47: 0.0060904455 | O47: 86.523928 | P47: 2.219154 | Q47: 24 | R47: 0.18005383 | S47: 0.031537029
...

Sheet Olivine
A1: DataSet/Point | B1: Comment | C1: Phase | D1: Category | E1: Shape | F1: Grain_Name | G1: Profile | H1: Profile_Number | I1: Profile_Name | J1: Paired_Grains | K1: Xenolith_Or_Sample | L1: Collection Date | M1: Marked_bad | N1: Ignore | O1: Na2O | P1: MgO | Q1: SiO2 | R1: CaO | S1: Cr2O3 | T1: FeO | U1: K2O | V1: Al2O3 | W1: P2O5 | X1: TiO2 | Y1: MnO | Z1: NiO | AA1: Total | AB1: Fo# | AC1: Cr# | AD1: X | AE1: Y | AF1: Z | AG1: Beam X | AH1: Beam Y | AI1: X-Distance from Edge | AJ1: Image_X | AK1: Image_Y | AL1: X_mm | AM1: Y_mm | AN1: Y_mm_offset | AO1: Edge distance x mm | AP1: Distance µm | AQ1: Core_Rim
B2: Primary core Summary | C2: olivine | D2: Summary Average | I2: =_xlfn.CONCAT(K2,"_",F2,"_",H2) -> GCB1__ | K2: GCB1 | L2: 43282 | N2: yes | P2: 49.595897 | Q2: 40.885497 | R2: 0.04524 | S2: 0.008973 | T2: 9.857125 | V2: 0.0046 | X2: 0.003969 | Y2: 0.156804 | Z2: 0.394084 | AA2: 100.95673 | AB2: 89.969033
B3: R-1_ol-1_A | C3: olivine | D3: Primary | I3: =_xlfn.CONCAT(K3,"_",F3,"_",H3) -> GCB1__ | K3: GCB1 | L3: 43282 | P3: 49.721075 | Q3: 40.58927 | R3: 0.04746 | S3: 0.01329 | T3: 9.796135 | V3: 0.006095 | X3: 0.006485 | Y3: 0.15288 | Z3: 0.39035 | AA3: 100.72305 | AB3: 90.047461 | AQ3: core
B4: R-2_ol-6_G | C4: olivine | D4: Primary | I4: =_xlfn.CONCAT(K4,"_",F4,"_",H4) -> GCB1__ | K4: GCB1 | L4: 43282 | P4: 49.594965 | Q4: 40.745685 | R4: 0.041135 | S4: 0.009435 | T4: 9.94514 | V4: 0.003685 | X4: 0.002205 | Y4: 0.14929 | Z4: 0.389885 | AA4: 100.8859 | AB4: 89.888346 | AQ4: core
B5: R-20_ol-1_A | C5: olivine | D5: Primary | I5: =_xlfn.CONCAT(K5,"_",F5,"_",H5) -> GCB1__ | K5: GCB1 | L5: 43282 | P5: 49.520297 | Q5: 41.017347 | R5: 0.047693333 | S5: 0.00465 | T5: 9.9032733 | V5: 0.0030433333 | X5: 0.0062533333 | Y5: 0.15866333 | Z5: 0.3976 | AA5: 101.0656 | AB5: 89.912978 | AQ5: core
B6: R-21_ol-1_C | C6: olivine | D6: Primary | I6: =_xlfn.CONCAT(K6,"_",F6,"_",H6) -> GCB1__ | K6: GCB1 | L6: 43282 | P6: 49.588667 | Q6: 41.04434 | R6: 0.044043333 | S6: 0.01011 | T6: 9.79296 | V6: 0.00577 | X6: 0.0011833333 | Y6: 0.16257 | Z6: 0.39585667 | AA6: 101.05087 | AB6: 90.026592 | AQ6: core
B7: Primary rim Summary | C7: olivine | D7: Summary Average | I7: =_xlfn.CONCAT(K7,"_",F7,"_",H7) -> GCB1__ | K7: GCB1 | L7: 43282 | N7: yes | P7: 49.780276 | Q7: 41.024326 | R7: 0.06201375 | S7: 0.01185375 | T7: 9.7502375 | V7: 0.00588125 | X7: 0.00541875 | Y7: 0.15616375 | Z7: 0.38431375 | AA7: 101.18466 | AB7: 90.100004
B8: R-1_ol-1_B | C8: olivine | D8: Primary | I8: =_xlfn.CONCAT(K8,"_",F8,"_",H8) -> GCB1__ | K8: GCB1 | L8: 43282 | P8: 49.954025 | Q8: 40.879695 | R8: 0.048945 | S8: 0.00787 | T8: 9.84532 | V8: 0.006425 | X8: 0.00366 | Y8: 0.15258 | Z8: 0.39483 | AA8: 101.29555 | AB8: 90.044481 | AQ8: rim
B9: R-20_ol-1_B | C9: olivine | D9: Primary | I9: =_xlfn.CONCAT(K9,"_",F9,"_",H9) -> GCB1__ | K9: GCB1 | L9: 43282 | P9: 49.581927 | Q9: 41.22382 | R9: 0.053596667 | S9: 0.014423333 | T9: 9.74458 | V9: 0.0059066667 | X9: 0.00916 | Y9: 0.16105667 | Z9: 0.38284 | AA9: 101.18617 | AB9: 90.069331 | AQ9: rim
B10: R-22_ol-1_A | C10: olivine | D10: Primary | I10: =_xlfn.CONCAT(K10,"_",F10,"_",H10) -> GCB1__ | K10: GCB1 | L10: 43282 | P10: 49.862793 | Q10: 40.921253 | R10: 0.079143333 | S10: 0.01194 | T10: 9.6925067 | V10: 0.0054933333 | X10: 0.00285 | Y10: 0.15366 | Z10: 0.37877667 | AA10: 101.10923 | AB10: 90.167693 | AQ10: rim
B11: Primary interior Summary | C11: olivine | D11: Summary Average | I11: =_xlfn.CONCAT(K11,"_",F11,"_",H11) -> GCB1__ | K11: GCB1 | L11: 43282 | N11: yes | P11: 50.041555 | Q11: 40.543496 | R11: 0.078200476 | S11: 0.03725381 | T11: 9.1139905 | V11: 0.013140476 | X11: 0.0053404762 | Y11: 0.14897 | Z11: 0.36070952 | AA11: 100.34664 | AB11: 90.728297
B12: Primary core Summary | C12: olivine | D12: Summary Average | I12: =_xlfn.CONCAT(K12,"_",F12,"_",H12) -> GCB1__ | K12: GCB1 | L12: 43282 | N12: yes | P12: 49.577903 | Q12: 40.493403 | R12: 0.043168889 | S12: 0.0068766667 | T12: 9.9486089 | V12: 0.0055111111 | X12: 0.0036422222 | Y12: 0.1623 | Z12: 0.36730111 | AA12: 100.61185 | AB12: 89.881576
B13: R-30_ol-1_A | C13: olivine | D13: Primary | I13: =_xlfn.CONCAT(K13,"_",F13,"_",H13) -> GCB1__ | K13: GCB1 | L13: 43282 | P13: 49.343437 | Q13: 40.42346 | R13: 0.046556667 | S13: 0.00883 | T13: 9.9300667 | V13: 0.00659 | X13: 0.0043233333 | Y13: 0.15913333 | Z13: 0.36854333 | AA13: 100.29248 | AB13: 89.855836 | AQ13: core
B14: R-31_ol-1_B | C14: olivine | D14: Primary | I14: =_xlfn.CONCAT(K14,"_",F14,"_",H14) -> GCB1__ | K14: GCB1 | L14: 43282 | P14: 49.844225 | Q14: 41.019935 | R14: 0.044725 | S14: 0.005075 | T14: 9.96317 | V14: 0.00706 | X14: 0.007885 | Y14: 0.167325 | Z14: 0.36395 | AA14: 101.42335 | AB14: 89.916978 | AQ14: core
B15: R-31_ol-3_A | C15: olivine | D15: Primary | I15: =_xlfn.CONCAT(K15,"_",F15,"_",H15) -> GCB1__ | K15: GCB1 | L15: 43282 | P15: 49.288305 | Q15: 40.00326 | R15: 0.03996 | S15: 0.003825 | T15: 10.004045 | X15: 0.002 | Y15: 0.160225 | Z15: 0.37028 | AA15: 99.878715 | AB15: 89.777729 | AQ15: core
B16: R-5_ol-4_A | C16: olivine | D16: Primary | I16: =_xlfn.CONCAT(K16,"_",F16,"_",H16) -> GCB1__ | K16: GCB1 | L16: 43282 | P16: 49.95288 | Q16: 40.56193 | R16: 0.03974 | S16: 0.0088 | T16: 9.906425 | V16: 0.007615 | X16: 2e-05 | Y16: 0.1641 | Z16: 0.36581 | AA16: 101.01255 | AB16: 89.988629 | AQ16: core
B17: Primary rim Summary | C17: olivine | D17: Summary Average | I17: =_xlfn.CONCAT(K17,"_",F17,"_",H17) -> GCB1__ | K17: GCB1 | L17: 43282 | N17: yes | P17: 49.862797 | Q17: 40.435381 | R17: 0.074184286 | S17: 0.022681429 | T17: 9.2404343 | V17: 0.010341429 | X17: 0.0070928571 | Y17: 0.15680429 | Z17: 0.35553 | AA17: 100.16889 | AB17: 90.581285
B18: R-30_ol-1_Rim | C18: olivine | D18: Primary | I18: =_xlfn.CONCAT(K18,"_",F18,"_",H18) -> GCB1__ | K18: GCB1 | L18: 43282 | P18: 50.185347 | Q18: 40.4899 | R18: 0.068573333 | S18: 0.023086667 | T18: 8.98306 | V18: 0.010706667 | X18: 0.0076633333 | Y18: 0.15149667 | Z18: 0.37084 | AA18: 100.29423 | AB18: 90.875009 | AQ18: rim
B19: R-31_ol-1_A | C19: olivine | D19: Primary | I19: =_xlfn.CONCAT(K19,"_",F19,"_",H19) -> GCB1__ | K19: GCB1 | L19: 43282 | P19: 49.136055 | Q19: 39.923905 | R19: 0.0557 | S19: 0.01486 | T19: 9.943 | V19: 0.015635 | X19: 0.008765 | Y19: 0.173235 | Z19: 0.374995 | AA19: 99.650985 | AB19: 89.805502 | AQ19: rim
B20: R-31_ol-3_Rim | C20: olivine | D20: Primary | I20: =_xlfn.CONCAT(K20,"_",F20,"_",H20) -> GCB1__ | K20: GCB1 | L20: 43282 | P20: 50.105715 | Q20: 40.86508 | R20: 0.101085 | S20: 0.029895 | T20: 8.92393 | V20: 0.0045 | X20: 0.004565 | Y20: 0.148335 | Z20: 0.3131 | AA20: 100.49879 | AB20: 90.916482 | AQ20: rim
B21: Melt Pocket Summary | C21: olivine | D21: Summary Average | I21: =_xlfn.CONCAT(K21,"_",F21,"_",H21) -> GCB1__ | K21: GCB1 | L21: 43282 | N21: yes | P21: 51.126388 | Q21: 40.785024 | R21: 0.14688 | S21: 0.112334 | T21: 7.434656 | V21: 0.030792 | X21: 0.005944 | Y21: 0.114008 | Z21: 0.356096 | AA21: 100.11809 | AB21: 92.458214
B22: R-30_ol-_melt pocket | C22: olivine | D22: MP | I22: =_xlfn.CONCAT(K22,"_",F22,"_",H22) -> GCB1__ | K22: GCB1 | L22: 43282 | P22: 51.312977 | Q22: 40.785257 | R22: 0.15059667 | S22: 0.13938333 | T22: 7.5459867 | V22: 0.032906667 | X22: 0.0047766667 | Y22: 0.11374333 | Z22: 0.35535 | AA22: 100.44853 | AB22: 92.37907
B23: R-31_ol-_melt pocket | C23: olivine | D23: MP | I23: =_xlfn.CONCAT(K23,"_",F23,"_",H23) -> GCB1__ | K23: GCB1 | L23: 43282 | P23: 50.846505 | Q23: 40.784675 | R23: 0.141305 | S23: 0.07176 | T23: 7.26766 | V23: 0.02762 | X23: 0.007695 | Y23: 0.114405 | Z23: 0.357215 | AA23: 99.622415 | AB23: 92.576929
B24: scoria Summary | C24: olivine | D24: Summary Average | I24: =_xlfn.CONCAT(K24,"_",F24,"_",H24) -> Scoria__ | K24: Scoria | L24: 43282 | N24: yes | P24: 47.505939 | Q24: 40.156763 | R24: 0.12242 | S24: 0.0235735 | T24: 12.394644 | V24: 0.023122 | X24: 0.0138515 | Y24: 0.1846305 | Z24: 0.323316 | AA24: 100.75712 | AB24: 87.192088
B25: Summary core Summary | C25: olivine | D25: Summary Average | I25: =_xlfn.CONCAT(K25,"_",F25,"_",H25) -> Scoria__ | K25: Scoria | L25: 43282 | N25: yes | P25: 48.574744 | Q25: 40.304346 | R25: 0.096471429 | S25: 0.028737143 | T25: 11.090179 | V25: 0.025947143 | X25: 0.0086657143 | Y25: 0.15979286 | Z25: 0.37633429 | AA25: 100.67361 | AB25: 88.64572
B26: Scoria_ol-2_A | C26: olivine | D26: Phenocryst | I26: =_xlfn.CONCAT(K26,"_",F26,"_",H26) -> Scoria__ | K26: Scoria | L26: 43282 | P26: 47.933453 | Q26: 40.759013 | R26: 0.14007333 | S26: 0.046443333 | T26: 11.922713 | V26: 0.045286667 | X26: 0.014396667 | Y26: 0.17379667 | Z26: 0.35171 | AA26: 101.3941 | AB26: 87.754983
B27: Scoria_ol-24_A | C27: olivine | D27: Phenocryst | I27: =_xlfn.CONCAT(K27,"_",F27,"_",H27) -> Scoria__ | K27: Scoria | L27: 43282 | P27: 48.12274 | Q27: 40.1636 | R27: 0.15565 | S27: 0.03997 | T27: 12.51844 | V27: 0.04002 | X27: 0.01239 | Y27: 0.20353 | Z27: 0.31522 | AA27: 101.5849 | AB27: 87.265295
B28: Scoria_ol-6_A | C28: olivine | D28: Phenocryst | I28: =_xlfn.CONCAT(K28,"_",F28,"_",H28) -> Scoria__ | K28: Scoria | L28: 43282 | P28: 49.366703 | Q28: 39.896593 | R28: 0.033143333 | S28: 0.0072866667 | T28: 9.7815567 | V28: 0.0019166667 | X28: 0.0016933333 | Y28: 0.13121 | Z28: 0.42133 | AA28: 99.649353 | AB28: 89.996597
B29: overgrowth summary | C29: olivine | D29: Summary Average | I29: =_xlfn.CONCAT(K29,"_",F29,"_",H29) -> Scoria__ | K29: Scoria | L29: 43282 | N29: yes | P29: 43.270897 | Q29: 39.50421 | R29: 0.29755667 | S29: 0.0162 | T29: 17.538013 | V29: 0.02727 | X29: 0.034326667 | Y29: 0.2924 | Z29: 0.13632667 | AA29: 101.12413 | AB29: 81.47391
B30: Scoria_ol-6_Rim_Overgrowth | C30: olivine | D30: Phenocryst | I30: =_xlfn.CONCAT(K30,"_",F30,"_",H30) -> Scoria__ | K30: Scoria | L30: 43282 | P30: 43.270897 | Q30: 39.50421 | R30: 0.29755667 | S30: 0.0162 | T30: 17.538013 | V30: 0.02727 | X30: 0.034326667 | Y30: 0.2924 | Z30: 0.13632667 | AA30: 101.12413 | AB30: 81.47391
B31: Scoria rim Summary | C31: olivine | D31: Summary Average | I31: =_xlfn.CONCAT(K31,"_",F31,"_",H31) -> Scoria__ | K31: Scoria | L31: 43282 | N31: yes | P31: 48.028288 | Q31: 40.249221 | R31: 0.088043 | S31: 0.022171 | T31: 11.76476 | V31: 0.0199 | X31: 0.011339 | Y31: 0.169686 | Z31: 0.3423 | AA31: 100.70547 | AB31: 87.89
B32: Scoria_ol-2_D | C32: olivine | D32: Phenocryst | I32: =_xlfn.CONCAT(K32,"_",F32,"_",H32) -> Scoria__ | K32: Scoria | L32: 43282 | P32: 45.385313 | Q32: 39.62035 | R32: 0.15215333 | S32: 0.03951 | T32: 15.116783 | V32: 0.037043333 | X32: 0.020606667 | Y32: 0.20622 | Z32: 0.23497 | AA32: 100.82867 | AB32: 84.253459
B33: Scoria_ol-24_C | C33: olivine | D33: Phenocryst | I33: =_xlfn.CONCAT(K33,"_",F33,"_",H33) -> Scoria__ | K33: Scoria | L33: 43282 | P33: 45.92887 | Q33: 38.45922 | R33: 0.15167 | S33: 0.03927 | T33: 14.99999 | V33: 0.05275 | X33: 0.01817 | Y33: 0.17944 | Z33: 0.26421 | AA33: 100.1132 | AB33: 84.515746
B34: Scoria_ol-6_E | C34: olivine | D34: Phenocryst | I34: =_xlfn.CONCAT(K34,"_",F34,"_",H34) -> Scoria__ | K34: Scoria | L34: 43282 | P34: 49.457723 | Q34: 41.423557 | R34: 0.04754 | S34: 0.010976667 | T34: 9.3699433 | V34: 0.00338 | X34: 0.00762 | Y34: 0.14486 | Z34: 0.41339 | AA34: 100.8847 | AB34: 90.392943
B35: Scoria_ol-6_Rim_before Overgrowth | C35: olivine | D35: Phenocryst | I35: =_xlfn.CONCAT(K35,"_",F35,"_",H35) -> Scoria__ | K35: Scoria | L35: 43282 | P35: 49.941633 | Q35: 40.300423 | R35: 0.043226667 | S35: 0.010326667 | T35: 9.7291433 | V35: 0.0083266667 | X35: 0.0035133333 | Y35: 0.15472667 | Z35: 0.40457 | AA35: 100.60047 | AB35: 90.148349
B36: R-11_ol-_melt pocket | C36: olivine | D36: MP | I36: =_xlfn.CONCAT(K36,"_",F36,"_",H36) -> MP__ | K36: MP | L36: 43282 | P36: 51.76302 | Q36: 40.946425 | R36: 0.20958 | S36: 0.10846 | T36: 6.833435 | V36: 0.03265 | X36: 0.00934 | Y36: 0.12209 | Z36: 0.37192 | AA36: 100.40545 | AB36: 93.104722
B37: San Carlos | C37: olivine | D37: Standard | I37: =_xlfn.CONCAT(K37,"_",F37,"_",H37) -> standard__ | K37: standard | L37: 43282 | N37: yes | P37: 49.11144 | Q37: 40.808777 | R37: 0.10538667 | S37: 0.01941 | T37: 9.7294733 | V37: 0.02388 | X37: 0.00574 | Y37: 0.15731667 | Z37: 0.37714667 | AA37: 100.34732 | AB37: 89.997874
I38: =_xlfn.CONCAT(K38,"_",F38,"_",H38) -> __
I39: =_xlfn.CONCAT(K39,"_",F39,"_",H39) -> __
A40: 1 / 1 . | B40: San_Carlos_EDS | C40: olivine | D40: Standard | I40: =_xlfn.CONCAT(K40,"_",F40,"_",H40) -> San Carlos__ | K40: San Carlos | L40: 44013 | N40: yes | P40: 49.73917 | Q40: 41.22001 | R40: 0.106488 | T40: 9.767123 | V40: 0.022128 | W40: 0.00313 | X40: 0.003756 | Y40: 0.128981 | Z40: 0.372289 | AA40: 101.3631 | AB40: 90.077224 | AD40: 7312 | AE40: 31440 | AF40: 35
...

Sheet CPX_Summary Molar 
A1: DataSet/Point | B1: Comment | C1: Phase | D1: Category | E1: Shape | F1: Grain_Name | G1: Profile_Number | H1: Paired_Grains | I1: Xenolith Or Sample | J1: Collection Date | K1: Na2O | L1: MgO | M1: SiO2 | N1: CaO | O1: Cr2O3 | P1: FeO | Q1: K2O | R1: Al2O3 | S1: P2O5 | T1: TiO2 | U1: MnO | V1: NiO | W1: Total | X1: Mg# | Y1: Cr# | Z1: X | AA1: Y | AB1: Z | AC1: X-Distance from Edge | AD1: Image_X | AE1: Image_Y | AF1: X_mm | AG1: Y_mm | AH1: Y_mm_offset | AI1: Edge distance x mm | AJ1: Grain Profile Distance to Rim | AM1: Molar | AN1: Na | AO1: Mg | AP1: Si | AQ1: Ca | AR1: Cr | AS1: Fe | AT1: K2 | AU1: Al | AV1: P | AW1: Ti | AX1: Mn | AY1: Ni | AZ1: Sum | BB1: Mole Fraction | BC1: Na | BD1: Mg | BE1: Si | BF1: Ca | BG1: Cr | BH1: Fe | BI1: K | BJ1: Al | BK1: P | BL1: Ti | BM1: Mn | BN1: Ni | BO1: Sum | BP1: Charge Def | BR1: SiO2 | BS1: CaTs AlIV | BT1: CrTs AlIV | BU1: TiTs AlIV | BV1: AlIV/STet | BW1: O'Leary Al(Tet) | BY1: M2 Al | BZ1: AlIV/Al total | CB1: Na/Ca | CC1: Na/Al
B2: exterior summary | C2: cpx | D2: summary avg | I2: GCB1 | J2: 43282 | K2: 0.475615 | L2: 17.048971 | M2: 52.825532 | N2: 22.786213 | O2: 0.53999813 | P2: 2.7434775 | R2: 3.9100169 | T2: 0.0994775 | U2: 0.1015675 | V2: 0.0458675 | W2: 100.57672 | X2: 91.719706 | Y2: =(O2/151.99)/((O2/151.99)+(R2/101.96))*100 -> 8.4790814 | AN2: =K2/'Molar Masses'!B$3*'Molar Masses'!B$4 -> 0.015347633 | AO2: =L2/'Molar Masses'!C$3*'Molar Masses'!C$4 -> 0.4230052 | AP2: =M2/'Molar Masses'!D$3*'Molar Masses'!D$4 -> 0.87919027 | AQ2: =N2/'Molar Masses'!E$3*'Molar Masses'!E$4 -> 0.40632056 | AR2: =O2/'Molar Masses'!F$3*'Molar Masses'!F$4 -> 0.007105706 | AS2: =P2/'Molar Masses'!G$3*'Molar Masses'!G$4 -> 0.038185316 | AT2: =Q2/'Molar Masses'!H$3*'Molar Masses'!H$4 -> 0 | AU2: =R2/'Molar Masses'!I$3*'Molar Masses'!I$4 -> 0.076696112 | ... AY2: =V2/'Molar Masses'!M$3*'Molar Masses'!M$4 -> 0.00061408195 | AZ2: =SUM(AN2:AY2) -> 1.8491422 | BC2: =AN2/$AZ2 -> 0.008299866 | BD2: =AO2/$AZ2 -> 0.22875752 | BE2: =AP2/$AZ2 -> 0.47545844 | BF2: =AQ2/$AZ2 -> 0.21973462 | BG2: =AR2/$AZ2 -> 0.0038427039 | BH2: =AS2/$AZ2 -> 0.020650286 | BI2: =AT2/$AZ2 -> 0 | BJ2: =AU2/$AZ2 -> 0.041476589 | ... BN2: =AY2/$AZ2 -> 0.00033209017 | BO2: =SUM(BC2:BN2) -> 1 | BP2: =(1.5-SUMPRODUCT(BC2:BN2,'Molar Masses'!$B$6:$M$6)) * 2 -> 0.010716528 | BR2: =BE2 -> 0.47545844 | BS2: =0.5*(BJ2-(BC2+BT2+BU2)) -> 0.013993424 | BT2: =BG2 -> 0.0038427039 | BU2: =2*BL2 -> 0.0013471706 | BV2: =SUM(BS2:BU2)/SUM(BR2:BU2) -> 0.038782208 | BW2: =BJ2-BC2 -> 0.033176723 | BY2: =BJ2-(0.5-BR2) -> 0.016935026 | BZ2: =BV2/BJ2 -> 0.93503851 | CB2: =BC2/BF2 -> 0.037772228 | CC2: =BC2/BJ2 -> 0.20010966
B3: Exterior core summary | C3: cpx | D3: summary avg | I3: GCB1 | J3: 43282 | K3: 0.472396 | L3: 17.035197 | M3: 52.839839 | N3: 22.782294 | O3: 0.531355 | P3: 2.722291 | R3: 3.908686 | T3: 0.100054 | U3: 0.101827 | V3: 0.040391 | W3: 100.53432 | X3: 91.771805 | Y3: =(O3/151.99)/((O3/151.99)+(R3/101.96))*100 -> 8.3573121 | AN3: =K3/'Molar Masses'!B$3*'Molar Masses'!B$4 -> 0.015243759 | AO3: =L3/'Molar Masses'!C$3*'Molar Masses'!C$4 -> 0.42266346 | AP3: =M3/'Molar Masses'!D$3*'Molar Masses'!D$4 -> 0.87942839 | AQ3: =N3/'Molar Masses'!E$3*'Molar Masses'!E$4 -> 0.40625067 | AR3: =O3/'Molar Masses'!F$3*'Molar Masses'!F$4 -> 0.0069919732 | AS3: =P3/'Molar Masses'!G$3*'Molar Masses'!G$4 -> 0.03789043 | AT3: =Q3/'Molar Masses'!H$3*'Molar Masses'!H$4 -> 0 | AU3: =R3/'Molar Masses'!I$3*'Molar Masses'!I$4 -> 0.076670006 | ... AY3: =V3/'Molar Masses'!M$3*'Molar Masses'!M$4 -> 0.00054076163 | AZ3: =SUM(AN3:AY3) -> 1.8483677 | BC3: =AN3/$AZ3 -> 0.0082471463 | BD3: =AO3/$AZ3 -> 0.2286685 | BE3: =AP3/$AZ3 -> 0.4757865 | BF3: =AQ3/$AZ3 -> 0.21978889 | BG3: =AR3/$AZ3 -> 0.0037827827 | BH3: =AS3/$AZ3 -> 0.020499401 | BI3: =AT3/$AZ3 -> 0 | BJ3: =AU3/$AZ3 -> 0.041479846 | ... BN3: =AY3/$AZ3 -> 0.00029256172 | BO3: =SUM(BC3:BN3) -> 1 | BP3: =(1.5-SUMPRODUCT(BC3:BN3,'Molar Masses'!$B$6:$M$6)) * 2 -> 0.010055969 | BR3: =BE3 -> 0.4757865 | BS3: =0.5*(BJ3-(BC3+BT3+BU3)) -> 0.014047186 | BT3: =BG3 -> 0.0037827827 | BU3: =2*BL3 -> 0.0013555457 | BV3: =SUM(BS3:BU3)/SUM(BR3:BU3) -> 0.038760806 | BW3: =BJ3-BC3 -> 0.0332327 | BY3: =BJ3-(0.5-BR3) -> 0.017266348 | BZ3: =BV3/BJ3 -> 0.93444912 | CB3: =BC3/BF3 -> 0.037523036 | CC3: =BC3/BJ3 -> 0.19882297
B4: R-20_cpx-1_A | C4: cpx | D4: Primary | I4: GCB1 | J4: 43282 | K4: 0.4794875 | L4: 17.172005 | M4: 52.755327 | N4: 22.79006 | O4: 0.55725 | P4: 2.705965 | R4: 3.92388 | T4: 0.09947 | U4: 0.1033375 | V4: 0.03901 | W4: 100.62578 | X4: 91.877177 | Y4: =(O4/151.99)/((O4/151.99)+(R4/101.96))*100 -> 8.6981839 | AN4: =K4/'Molar Masses'!B$3*'Molar Masses'!B$4 -> 0.015472594 | AO4: =L4/'Molar Masses'!C$3*'Molar Masses'!C$4 -> 0.42605782 | AP4: =M4/'Molar Masses'!D$3*'Molar Masses'!D$4 -> 0.87802184 | AQ4: =N4/'Molar Masses'!E$3*'Molar Masses'!E$4 -> 0.40638916 | AR4: =O4/'Molar Masses'!F$3*'Molar Masses'!F$4 -> 0.0073327193 | AS4: =P4/'Molar Masses'!G$3*'Molar Masses'!G$4 -> 0.037663195 | AT4: =Q4/'Molar Masses'!H$3*'Molar Masses'!H$4 -> 0 | AU4: =R4/'Molar Masses'!I$3*'Molar Masses'!I$4 -> 0.076968041 | ... AY4: =V4/'Molar Masses'!M$3*'Molar Masses'!M$4 -> 0.00052227256 | AZ4: =SUM(AN4:AY4) -> 1.8511298 | BC4: =AN4/$AZ4 -> 0.0083584598 | BD4: =AO4/$AZ4 -> 0.23016096 | BE4: =AP4/$AZ4 -> 0.47431672 | BF4: =AQ4/$AZ4 -> 0.21953574 | BG4: =AR4/$AZ4 -> 0.0039612128 | BH4: =AS4/$AZ4 -> 0.020346058 | BI4: =AT4/$AZ4 -> 0 | BJ4: =AU4/$AZ4 -> 0.041578953 | ... BN4: =AY4/$AZ4 -> 0.00028213718 | BO4: =SUM(BC4:BN4) -> 1 | BP4: =(1.5-SUMPRODUCT(BC4:BN4,'Molar Masses'!$B$6:$M$6)) * 2 -> 0.012839229 | BR4: =BE4 -> 0.47431672 | BS4: =0.5*(BJ4-(BC4+BT4+BU4)) -> 0.013956829 | BT4: =BG4 -> 0.0039612128 | BU4: =2*BL4 -> 0.0013456227 | BV4: =SUM(BS4:BU4)/SUM(BR4:BU4) -> 0.039028424 | BW4: =BJ4-BC4 -> 0.033220493 | BY4: =BJ4-(0.5-BR4) -> 0.015895674 | BZ4: =BV4/BJ4 -> 0.93865816 | CB4: =BC4/BF4 -> 0.038073345 | CC4: =BC4/BJ4 -> 0.20102622
B5: R-21_cpx-1_B | C5: cpx | D5: Primary | I5: GCB1 | J5: 43282 | K5: 0.47114333 | L5: 16.831303 | M5: 52.564087 | N5: 22.730527 | O5: 0.57247 | P5: 2.7486267 | R5: 3.96884 | T5: 0.096473333 | U5: 0.10085667 | V5: 0.045616667 | W5: 100.12994 | X5: 91.608178 | Y5: =(O5/151.99)/((O5/151.99)+(R5/101.96))*100 -> 8.8224994 | AN5: =K5/'Molar Masses'!B$3*'Molar Masses'!B$4 -> 0.015203336 | AO5: =L5/'Molar Masses'!C$3*'Molar Masses'!C$4 -> 0.41760461 | AP5: =M5/'Molar Masses'!D$3*'Molar Masses'!D$4 -> 0.87483896 | AQ5: =N5/'Molar Masses'!E$3*'Molar Masses'!E$4 -> 0.40532757 | AR5: =O5/'Molar Masses'!F$3*'Molar Masses'!F$4 -> 0.0075329956 | AS5: =P5/'Molar Masses'!G$3*'Molar Masses'!G$4 -> 0.038256985 | AT5: =Q5/'Molar Masses'!H$3*'Molar Masses'!H$4 -> 0 | AU5: =R5/'Molar Masses'!I$3*'Molar Masses'!I$4 -> 0.077849945 | ... AY5: =V5/'Molar Masses'!M$3*'Molar Masses'!M$4 -> 0.00061072375 | AZ5: =SUM(AN5:AY5) -> 1.8398548 | BC5: =AN5/$AZ5 -> 0.0082633347 | BD5: =AO5/$AZ5 -> 0.22697694 | BE5: =AP5/$AZ5 -> 0.47549347 | BF5: =AQ5/$AZ5 -> 0.2203041 | BG5: =AR5/$AZ5 -> 0.0040943424 | BH5: =AS5/$AZ5 -> 0.02079348 | BI5: =AT5/$AZ5 -> 0 | BJ5: =AU5/$AZ5 -> 0.042313091 | ... BN5: =AY5/$AZ5 -> 0.00033194127 | BO5: =SUM(BC5:BN5) -> 1 | BP5: =(1.5-SUMPRODUCT(BC5:BN5,'Molar Masses'!$B$6:$M$6)) * 2 -> 0.0095558771 | BR5: =BE5 -> 0.47549347 | BS5: =0.5*(BJ5-(BC5+BT5+BU5)) -> 0.014321166 | BT5: =BG5 -> 0.0040943424 | BU5: =2*BL5 -> 0.0013130818 | BV5: =SUM(BS5:BU5)/SUM(BR5:BU5) -> 0.039837866 | BW5: =BJ5-BC5 -> 0.034049756 | BY5: =BJ5-(0.5-BR5) -> 0.017806562 | BZ5: =BV5/BJ5 -> 0.94150215 | CB5: =BC5/BF5 -> 0.037508765 | CC5: =BC5/BJ5 -> 0.19529026
B6: R-22_cpx-1_C | C6: cpx | D6: Primary | I6: GCB1 | J6: 43282 | K6: 0.46419333 | L6: 17.05668 | M6: 53.228273 | N6: 22.823707 | O6: 0.45571333 | P6: 2.7177233 | R6: 3.8282733 | T6: 0.10441333 | U6: 0.10078333 | V6: 0.037006667 | W6: 100.81677 | X6: 91.794937 | Y6: =(O6/151.99)/((O6/151.99)+(R6/101.96))*100 -> 7.3949979 | AN6: =K6/'Molar Masses'!B$3*'Molar Masses'!B$4 -> 0.014979067 | AO6: =L6/'Molar Masses'!C$3*'Molar Masses'!C$4 -> 0.42319647 | AP6: =M6/'Molar Masses'!D$3*'Molar Masses'!D$4 -> 0.88589321 | AQ6: =N6/'Molar Masses'!E$3*'Molar Masses'!E$4 -> 0.40698914 | AR6: =O6/'Molar Masses'!F$3*'Molar Masses'!F$4 -> 0.0059966226 | AS6: =P6/'Molar Masses'!G$3*'Molar Masses'!G$4 -> 0.037826855 | AT6: =Q6/'Molar Masses'!H$3*'Molar Masses'!H$4 -> 0 | AU6: =R6/'Molar Masses'!I$3*'Molar Masses'!I$4 -> 0.075092689 | ... AY6: =V6/'Molar Masses'!M$3*'Molar Masses'!M$4 -> 0.00049545159 | AZ6: =SUM(AN6:AY6) -> 1.8531976 | BC6: =AN6/$AZ6 -> 0.0080828221 | BD6: =AO6/$AZ6 -> 0.22836015 | BE6: =AP6/$AZ6 -> 0.47803494 | BF6: =AQ6/$AZ6 -> 0.21961454 | BG6: =AR6/$AZ6 -> 0.0032358247 | BH6: =AS6/$AZ6 -> 0.020411668 | BI6: =AT6/$AZ6 -> 0 | BJ6: =AU6/$AZ6 -> 0.040520605 | ... BN6: =AY6/$AZ6 -> 0.00026734958 | BO6: =SUM(BC6:BN6) -> 1 | BP6: =(1.5-SUMPRODUCT(BC6:BN6,'Molar Masses'!$B$6:$M$6)) * 2 -> 0.0068455857 | BR6: =BE6 -> 0.47803494 | BS6: =0.5*(BJ6-(BC6+BT6+BU6)) -> 0.013895519 | BT6: =BG6 -> 0.0032358247 | BU6: =2*BL6 -> 0.0014109197 | BV6: =SUM(BS6:BU6)/SUM(BR6:BU6) -> 0.037340143 | BW6: =BJ6-BC6 -> 0.032437783 | BY6: =BJ6-(0.5-BR6) -> 0.018555549 | BZ6: =BV6/BJ6 -> 0.92150999 | CB6: =BC6/BF6 -> 0.036804586 | CC6: =BC6/BJ6 -> 0.19947437
B7: exterior rim summary | C7: cpx | D7: summary avg | I7: GCB1 | J7: 43282 | K7: 0.48098 | L7: 17.071927 | M7: 52.801687 | N7: 22.792745 | O7: 0.55440333 | P7: 2.7787883 | R7: 3.912235 | T7: 0.098516667 | U7: 0.101135 | V7: 0.054995 | W7: 100.64738 | X7: 91.632873 | Y7: =(O7/151.99)/((O7/151.99)+(R7/101.96))*100 -> 8.6811296 | AN7: =K7/'Molar Masses'!B$3*'Molar Masses'!B$4 -> 0.015520756 | AO7: =L7/'Molar Masses'!C$3*'Molar Masses'!C$4 -> 0.42357476 | AP7: =M7/'Molar Masses'!D$3*'Molar Masses'!D$4 -> 0.87879341 | AQ7: =N7/'Molar Masses'!E$3*'Molar Masses'!E$4 -> 0.40643703 | AR7: =O7/'Molar Masses'!F$3*'Molar Masses'!F$4 -> 0.0072952607 | AS7: =P7/'Molar Masses'!G$3*'Molar Masses'!G$4 -> 0.038676793 | AT7: =Q7/'Molar Masses'!H$3*'Molar Masses'!H$4 -> 0 | AU7: =R7/'Molar Masses'!I$3*'Molar Masses'!I$4 -> 0.076739621 | ... AY7: =V7/'Molar Masses'!M$3*'Molar Masses'!M$4 -> 0.00073628248 | AZ7: =SUM(AN7:AY7) -> 1.8504331 | BC7: =AN7/$AZ7 -> 0.008387634 | BD7: =AO7/$AZ7 -> 0.22890574 | BE7: =AP7/$AZ7 -> 0.47491227 | BF7: =AQ7/$AZ7 -> 0.21964427 | BG7: =AR7/$AZ7 -> 0.0039424611 | BH7: =AS7/$AZ7 -> 0.020901481 | BI7: =AT7/$AZ7 -> 0 | BJ7: =AU7/$AZ7 -> 0.041471167 | ... BN7: =AY7/$AZ7 -> 0.00039789737 | BO7: =SUM(BC7:BN7) -> 1 | BP7: =(1.5-SUMPRODUCT(BC7:BN7,'Molar Masses'!$B$6:$M$6)) * 2 -> 0.011816232 | BR7: =BE7 -> 0.47491227 | BS7: =0.5*(BJ7-(BC7+BT7+BU7)) -> 0.013903922 | BT7: =BG7 -> 0.0039424611 | BU7: =2*BL7 -> 0.0013332278 | BV7: =SUM(BS7:BU7)/SUM(BR7:BU7) -> 0.038817903 | BW7: =BJ7-BC7 -> 0.033083533 | BY7: =BJ7-(0.5-BR7) -> 0.01638344 | BZ7: =BV7/BJ7 -> 0.93602148 | CB7: =BC7/BF7 -> 0.038187357 | CC7: =BC7/BJ7 -> 0.20225218
B8: R-20_cpx-1_B | C8: cpx | D8: Primary | I8: GCB1 | J8: 43282 | K8: 0.48651667 | L8: 17.066947 | M8: 52.390387 | N8: 22.807563 | O8: 0.58353 | P8: 2.7784467 | R8: 3.94813 | T8: 0.099026667 | U8: 0.09764 | V8: 0.052036667 | W8: 100.3102 | X8: 91.632109 | Y8: =(O8/151.99)/((O8/151.99)+(R8/101.96))*100 -> 9.0204904 | AN8: =K8/'Molar Masses'!B$3*'Molar Masses'!B$4 -> 0.015699419 | AO8: =L8/'Molar Masses'!C$3*'Molar Masses'!C$4 -> 0.4234512 | AP8: =M8/'Molar Masses'!D$3*'Molar Masses'!D$4 -> 0.87194802 | AQ8: =N8/'Molar Masses'!E$3*'Molar Masses'!E$4 -> 0.40670127 | AR8: =O8/'Molar Masses'!F$3*'Molar Masses'!F$4 -> 0.0076785315 | AS8: =P8/'Molar Masses'!G$3*'Molar Masses'!G$4 -> 0.038672037 | AT8: =Q8/'Molar Masses'!H$3*'Molar Masses'!H$4 -> 0 | AU8: =R8/'Molar Masses'!I$3*'Molar Masses'!I$4 -> 0.077443712 | ... AY8: =V8/'Molar Masses'!M$3*'Molar Masses'!M$4 -> 0.00069667581 | AZ8: =SUM(AN8:AY8) -> 1.8449072 | BC8: =AN8/$AZ8 -> 0.008509598 | BD8: =AO8/$AZ8 -> 0.22952439 | BE8: =AP8/$AZ8 -> 0.47262432 | BF8: =AQ8/$AZ8 -> 0.22044538 | BG8: =AR8/$AZ8 -> 0.004162015 | BH8: =AS8/$AZ8 -> 0.020961508 | BI8: =AT8/$AZ8 -> 0 | BJ8: =AU8/$AZ8 -> 0.041977023 | ... BN8: =AY8/$AZ8 -> 0.00037762105 | BO8: =SUM(BC8:BN8) -> 1 | BP8: =(1.5-SUMPRODUCT(BC8:BN8,'Molar Masses'!$B$6:$M$6)) * 2 -> 0.015777767 | BR8: =BE8 -> 0.47262432 | BS8: =0.5*(BJ8-(BC8+BT8+BU8)) -> 0.013980633 | BT8: =BG8 -> 0.004162015 | BU8: =2*BL8 -> 0.0013441437 | BV8: =SUM(BS8:BU8)/SUM(BR8:BU8) -> 0.039598357 | BW8: =BJ8-BC8 -> 0.033467425 | BY8: =BJ8-(0.5-BR8) -> 0.014601347 | BZ8: =BV8/BJ8 -> 0.9433341 | CB8: =BC8/BF8 -> 0.038601843 | CC8: =BC8/BJ8 -> 0.20272038
B9: R-22_cpx-1_A | C9: cpx | D9: Primary | I9: GCB1 | J9: 43282 | K9: 0.47544333 | L9: 17.076907 | M9: 53.212987 | N9: 22.777927 | O9: 0.52527667 | P9: 2.77913 | R9: 3.87634 | T9: 0.098006667 | U9: 0.10463 | V9: 0.057953333 | W9: 100.98457 | X9: 91.633638 | Y9: =(O9/151.99)/((O9/151.99)+(R9/101.96))*100 -> 8.3328715 | AN9: =K9/'Molar Masses'!B$3*'Molar Masses'!B$4 -> 0.015342093 | AO9: =L9/'Molar Masses'!C$3*'Molar Masses'!C$4 -> 0.42369832 | AP9: =M9/'Molar Masses'!D$3*'Molar Masses'!D$4 -> 0.88563879 | AQ9: =N9/'Molar Masses'!E$3*'Molar Masses'!E$4 -> 0.4061728 | AR9: =O9/'Molar Masses'!F$3*'Molar Masses'!F$4 -> 0.0069119898 | AS9: =P9/'Molar Masses'!G$3*'Molar Masses'!G$4 -> 0.038681548 | AT9: =Q9/'Molar Masses'!H$3*'Molar Masses'!H$4 -> 0 | AU9: =R9/'Molar Masses'!I$3*'Molar Masses'!I$4 -> 0.07603553 | ... AY9: =V9/'Molar Masses'!M$3*'Molar Masses'!M$4 -> 0.00077588915 | AZ9: =SUM(AN9:AY9) -> 1.8559591 | BC9: =AN9/$AZ9 -> 0.0082663963 | BD9: =AO9/$AZ9 -> 0.22829077 | BE9: =AP9/$AZ9 -> 0.4771866 | BF9: =AQ9/$AZ9 -> 0.21884793 | BG9: =AR9/$AZ9 -> 0.0037242146 | BH9: =AS9/$AZ9 -> 0.020841811 | BI9: =AT9/$AZ9 -> 0 | BJ9: =AU9/$AZ9 -> 0.040968323 | ... BN9: =AY9/$AZ9 -> 0.00041805295 | BO9: =SUM(BC9:BN9) -> 1 | BP9: =(1.5-SUMPRODUCT(BC9:BN9,'Molar Masses'!$B$6:$M$6)) * 2 -> 0.0078782862 | BR9: =BE9 -> 0.4771866 | BS9: =0.5*(BJ9-(BC9+BT9+BU9)) -> 0.013827668 | BT9: =BG9 -> 0.0037242146 | BU9: =2*BL9 -> 0.001322377 | BV9: =SUM(BS9:BU9)/SUM(BR9:BU9) -> 0.038048274 | BW9: =BJ9-BC9 -> 0.032701927 | BY9: =BJ9-(0.5-BR9) -> 0.018154921 | BZ9: =BV9/BJ9 -> 0.92872421 | CB9: =BC9/BF9 -> 0.037772331 | CC9: =BC9/BJ9 -> 0.20177531
